<?xml version="1.0" encoding="utf-8"?>
<!-- This URDF was automatically created by SolidWorks to URDF Exporter! Originally created by Stephen Brawner (brawner@gmail.com) 
     Commit Version: 1.6.0-4-g7f85cfe  Build Version: 1.6.7995.38578
     For more information, please see http://wiki.ros.org/sw_urdf_exporter -->
<robot
  name="02-AMR-L_urdf">
<mujoco>
    <compiler meshdir="../../meshes/v3.2/" balanceinertia="true" discardvisual="false" />
  </mujoco>

  <link
    name="base_link-L">
    <inertial>
      <origin
        xyz="5.34736339306887E-05 -1.65509984368212E-06 0.0126065711781341"
        rpy="0 0 0" />
      <mass
        value="0.17676937015142" />
      <inertia
        ixx="6.98013171527675E-05"
        ixy="-1.32834828949302E-08"
        ixz="-2.63043929688913E-07"
        iyy="6.80954323895103E-05"
        iyz="8.54322983487787E-08"
        izz="8.89197435921882E-05" />
    </inertial>
    <visual>
      <origin
        xyz="0 0 0"
        rpy="0 0 0" />
      <geometry>
        <mesh
          filename="package://armcontrol/meshes/v3.2/base_link-L.STL" />
      </geometry>
      <material
        name="">
        <color
          rgba="0.752941176470588 0.752941176470588 0.752941176470588 1" />
      </material>
    </visual>
    <collision>
      <origin
        xyz="0 0 0.020125"
        rpy="0 0 0" />
      <geometry>
        <cylinder length="0.04025" radius="0.04"/>
      </geometry>
    </collision>
  </link>
  <link
    name="Link1-l">
    <inertial>
      <origin
        xyz="-0.0088527831789069 -0.000280590559863228 0.0670633884888944"
        rpy="0 0 0" />
      <mass
        value="0.397204281044318" />
      <inertia
        ixx="0.00037007701464005"
        ixy="-1.06759276237838E-06"
        ixz="4.91266150529164E-05"
        iyy="0.000386592571589103"
        iyz="2.22017036951604E-09"
        izz="0.000177520078090261" />
    </inertial>
    <visual>
      <origin
        xyz="0 0 0"
        rpy="0 0 0" />
      <geometry>
        <mesh
          filename="package://armcontrol/meshes/v3.2/Link1-l.STL" />
      </geometry>
      <material
        name="">
        <color
          rgba="0.752941176470588 0.752941176470588 0.752941176470588 1" />
      </material>
    </visual>
    <collision>
      <origin
        xyz="0 0 0.063725"
        rpy="0 0 0" />
      <geometry>
        <cylinder length="0.13745" radius="0.046"/>
      </geometry>
    </collision>
  </link>
  <joint
    name="joint1-l"
    type="revolute">
    <origin
      xyz="0 0 0.04025"
      rpy="0 0 0" />
    <parent
      link="base_link-L" />
    <child
      link="Link1-l" />
    <axis
      xyz="0 0 1" />
    <limit
      lower="-3.14"
      upper="1.05"
      effort="0"
      velocity="0" />
  </joint>
  <link
    name="Link2-l">
    <inertial>
      <origin
        xyz="0.0601388137965669 -1.86398061645943E-05 -0.0192816864312512"
        rpy="0 0 0" />
      <mass
        value="0.290860547989757" />
      <inertia
        ixx="0.000147541815496127"
        ixy="3.03151131088683E-07"
        ixz="5.20878529456631E-05"
        iyy="0.000239192935471383"
        iyz="-2.51820051634218E-07"
        izz="0.000208737092360013" />
    </inertial>
    <visual>
      <origin
        xyz="0 0 0"
        rpy="0 0 0" />
      <geometry>
        <mesh
          filename="package://armcontrol/meshes/v3.2/Link2-l.STL" />
      </geometry>
      <material
        name="">
        <color
          rgba="0.752941176470588 0.752941176470588 0.752941176470588 1" />
      </material>
    </visual>
    <collision>
      <origin
        xyz="0.041625 0 -0.024"
        rpy="0 1.57 0" />
      <geometry>
        <cylinder length="0.13925" radius="0.043"/>
      </geometry>
    </collision>
  </link>
  <joint
    name="joint2-l"
    type="revolute">
    <origin
      xyz="0.0279999999999102 0 0.0994500000000568"
      rpy="1.57079632679435 0 1.57079632679531" />
    <parent
      link="Link1-l" />
    <child
      link="Link2-l" />
    <axis
      xyz="0 0 1" />
    <limit
      lower="-0.44"
      upper="3.58"
      effort="0"
      velocity="0" />
  </joint>
  <link
    name="Link3-l">
    <inertial>
      <origin
        xyz="-1.61505789016418E-05 -0.00859970560887796 0.0847583674837915"
        rpy="0 0 0" />
      <mass
        value="0.396418729186788" />
      <inertia
        ixx="0.000614875814456579"
        ixy="-4.4403810120111E-07"
        ixz="6.0834447162288E-07"
        iyy="0.000578190709796366"
        iyz="8.65425690503897E-05"
        izz="0.000190763872781172" />
    </inertial>
    <visual>
      <origin
        xyz="0 0 0"
        rpy="0 0 0" />
      <geometry>
        <mesh
          filename="package://armcontrol/meshes/v3.2/Link3-l.STL" />
      </geometry>
      <material
        name="">
        <color
          rgba="0.752941176470588 0.752941176470588 0.752941176470588 1" />
      </material>
    </visual>
    <collision>
      <origin
        xyz="0 -0.006 0.075125"
        rpy="0 0 0" />
      <geometry>
        <cylinder length="0.15025" radius="0.045"/>
      </geometry>
    </collision>
  </link>
  <joint
    name="joint3-l"
    type="revolute">
    <origin
      xyz="0.111250000000011 0 -0.028000000000074"
      rpy="0 1.5707963267949 0" />
    <parent
      link="Link2-l" />
    <child
      link="Link3-l" />
    <axis
      xyz="0 0 1" />
    <limit
      lower="-2.76"
      upper="2.76"
      effort="0"
      velocity="0" />
  </joint>
  <link
    name="Link4-l">
    <inertial>
      <origin
        xyz="2.54861003970201E-05 0.0483397572535632 -0.016408443696572"
        rpy="0 0 0" />
      <mass
        value="0.218783739893838" />
      <inertia
        ixx="0.000193301035431187"
        ixy="-2.9080463842973E-07"
        ixz="2.46776176047075E-07"
        iyy="0.000117493591620785"
        iyz="4.85495668159927E-05"
        izz="0.000165622428811768" />
    </inertial>
    <visual>
      <origin
        xyz="0 0 0"
        rpy="0 0 0" />
      <geometry>
        <mesh
          filename="package://armcontrol/meshes/v3.2/Link4-l.STL" />
      </geometry>
      <material
        name="">
        <color
          rgba="0.752941176470588 0.752941176470588 0.752941176470588 1" />
      </material>
    </visual>
    <collision>
      <origin
        xyz="0 0.0365 -0.024"
        rpy="-1.57 0 0" />
      <geometry>
        <cylinder length="0.129" radius="0.043"/>
      </geometry>
    </collision>
  </link>
  <joint
    name="joint4-l"
    type="revolute">
    <origin
      xyz="0 0.0279999999999433 0.122249999999981"
      rpy="1.57079632679497 0 -3.14159265358979" />
    <parent
      link="Link3-l" />
    <child
      link="Link4-l" />
    <axis
      xyz="0 0 1" />
    <limit
      lower="-1.95"
      upper="1.95"
      effort="0"
      velocity="0" />
  </joint>
  <link
    name="Link5-l">
    <inertial>
      <origin
        xyz="-2.57864961277217E-05 -0.00699359132538249 0.0804176079432127"
        rpy="0 0 0" />
      <mass
        value="0.358803115126771" />
      <inertia
        ixx="0.000550931633053741"
        ixy="-4.34820357535642E-07"
        ixz="6.73567671403632E-07"
        iyy="0.000534869991985675"
        iyz="6.29982135448906E-05"
        izz="0.000159117060047407" />
    </inertial>
    <visual>
      <origin
        xyz="0 0 0"
        rpy="0 0 0" />
      <geometry>
        <mesh
          filename="package://armcontrol/meshes/v3.2/Link5-l.STL" />
      </geometry>
      <material
        name="">
        <color
          rgba="0.752941176470588 0.752941176470588 0.752941176470588 1" />
      </material>
    </visual>
    <collision>
      <origin
        xyz="0 -0.004 0.074"
        rpy="0 0 0" />
      <geometry>
        <cylinder length="0.148" radius="0.041"/>
      </geometry>
    </collision>
  </link>
  <joint
    name="joint5-l"
    type="revolute">
    <origin
      xyz="0 0.101000000000006 -0.0279999999999686"
      rpy="-1.57079632679468 0 0" />
    <parent
      link="Link4-l" />
    <child
      link="Link5-l" />
    <axis
      xyz="0 0 1" />
    <limit
      lower="-2.33"
      upper="2.33"
      effort="0"
      velocity="0" />
  </joint>
  <link
    name="Link6-l">
    <inertial>
      <origin
        xyz="7.24314019760282E-06 -0.0620765900836516 -0.0170572286366676"
        rpy="0 0 0" />
      <mass
        value="0.272133556207313" />
      <inertia
        ixx="0.000273282402295948"
        ixy="4.65808369841471E-08"
        ixz="3.84448427316228E-08"
        iyy="0.000137303774846917"
        iyz="-6.07315104590688E-05"
        izz="0.000247799169688693" />
    </inertial>
    <visual>
      <origin
        xyz="0 0 0"
        rpy="0 0 0" />
      <geometry>
        <mesh
          filename="package://armcontrol/meshes/v3.2/Link6-l.STL" />
      </geometry>
      <material
        name="">
        <color
          rgba="0.592156862745098 0.666666666666667 0.682352941176471 1" />
      </material>
    </visual>
    <collision>
      <origin
        xyz="0 -0.042 -0.01975"
        rpy="1.57 0 0" />
      <geometry>
        <cylinder length="0.14" radius="0.044"/>
      </geometry>
    </collision>
  </link>
  <joint
    name="joint6-l"
    type="revolute">
    <origin
      xyz="0 0.0237500000000851 0.119999999999995"
      rpy="-1.57079632679507 0 0" />
    <parent
      link="Link5-l" />
    <child
      link="Link6-l" />
    <axis
      xyz="0 0 1" />
    <limit
      lower="-2.1"
      upper="2.1"
      effort="0"
      velocity="0" />
  </joint>
  <link
    name="link7-l">
    <inertial>
      <origin
        xyz="1.4514188653119E-16 -9.43689570931383E-16 0.00336447801573792"
        rpy="0 0 0" />
      <mass
        value="0.0156367952000345" />
      <inertia
        ixx="1.24351573484494E-06"
        ixy="-5.82427994862809E-21"
        ixz="1.8051907006134E-19"
        iyy="1.2135847017907E-06"
        iyz="-1.93482760277248E-21"
        izz="2.32930826541179E-06" />
    </inertial>
    <visual>
      <origin
        xyz="0 0 0"
        rpy="0 0 0" />
      <geometry>
        <mesh
          filename="package://armcontrol/meshes/v3.2/link7-l.STL" />
      </geometry>
      <material
        name="">
        <color
          rgba="0.898039215686275 0.917647058823529 0.929411764705882 1" />
      </material>
    </visual>
    <collision>
      <origin
        xyz="0 0.00468 0.0035"
        rpy="0 0 0" />
      <geometry>
        <cylinder length="0.007" radius="0.03"/>
      </geometry>
    </collision>
  </link>
  <joint
    name="joint7-l"
    type="revolute">
    <origin
      xyz="0 -0.112000000000003 -0.0282500000000299"
      rpy="1.57079632679504 0 0" />
    <parent
      link="Link6-l" />
    <child
      link="link7-l" />
    <axis
      xyz="0 0 1" />
    <limit
      lower="-3.14"
      upper="3.15"
      effort="0"
      velocity="0" />
  </joint>
  <!-- <link
    name="Link-load-l">
    <inertial>
      <origin
        xyz="-1.154248523663E-13 2.76445533131664E-14 -0.0764999999999999"
        rpy="0 0 0" />
      <mass
        value="0.129779192519794" />
      <inertia
        ixx="0.000256411239620983"
        ixy="-8.92108835369458E-23"
        ixz="-3.77084068393609E-16"
        iyy="0.000256411239620983"
        iyz="5.71757067233944E-17"
        izz="6.48895962598972E-06" />
    </inertial>
    <visual>
      <origin
        xyz="0 0 0"
        rpy="0 0 0" />
      <geometry>
        <mesh
          filename="package://armcontrol/meshes/v3.2/Link-load-l.STL" />
      </geometry>
      <material
        name="">
        <color
          rgba="0.898039215686275 0.917647058823529 0.929411764705882 1" />
      </material>
    </visual>
    <collision>
      <origin
        xyz="0 0 0"
        rpy="0 0 0" />
      <geometry>
        <mesh
          filename="package://armcontrol/meshes/v3.2/Link-load-l.STL" />
      </geometry>
    </collision> 
  </link>-->
  <link
    name="left_load" />
  <joint
    name="left_load_joint"
    type="fixed">
    <origin
      xyz="0 0 0.16"
      rpy="0 0 0" />
    <parent
      link="link7-l" />
    <child
      link="left_load" />
    <axis
      xyz="0 0 0" />
  </joint>
</robot>
