<?xml version="1.0" encoding="utf-8"?>
<!-- This URDF was automatically created by SolidWorks to URDF Exporter! Originally created by
Stephen Brawner (brawner@gmail.com) 
     Commit Version: 1.6.0-4-g7f85cfe  Build Version: 1.6.7995.38578
     For more information, please see http://wiki.ros.org/sw_urdf_exporter -->
<robot
  name="robot_damiao_v1.0">
  <mujoco>
    <compiler meshdir="../../meshes/v1.0/" balanceinertia="true" discardvisual="false" />
  </mujoco>
  <link name="base">
    <visual>
      <origin xyz="0 0 0.75" />
      <geometry>
        <box size="0.2 0.2 1.5" />
      </geometry>
    </visual>
    <collision>
      <origin xyz="0 0 0.75" />
      <geometry>
        <box size="0.2 0.2 1.5" />
      </geometry>
    </collision>
  </link>
  <link name="nose">
    <visual>
      <origin xyz="0 0 0" />
      <geometry>
        <sphere radius="0.1" />
      </geometry>
      <material name="">
        <color rgba="1 0 0 1" />
      </material>
    </visual>
    <collision>
      <origin xyz="0 0 0" />
      <geometry>
        <sphere radius="0.1" />
      </geometry>
    </collision>
  </link>
  <joint
    name="nose_joint"
    type="fixed">
    <origin
      xyz="0 0.2 1.4"
      rpy="0 0 0" />
    <parent
      link="base" />
    <child
      link="nose" />
  </joint>

  <link
    name="left_base_link">
    <inertial>
      <origin
        xyz="-2.8968E-05 1.7287E-05 0.024802"
        rpy="0 0 0" />
      <mass
        value="0.24339" />
      <inertia
        ixx="9.5418E-05"
        ixy="-1.1246E-08"
        ixz="-4.7318E-08"
        iyy="9.5362E-05"
        iyz="3.0385E-08"
        izz="0.00014543" />
    </inertial>
    <visual>
      <origin
        xyz="0 0 0"
        rpy="0 0 0" />
      <geometry>
        <mesh
          filename="package://armcontrol/meshes/v1.0/left_base_link.STL" />
      </geometry>
      <material
        name="">
        <color
          rgba="1 1 1 1" />
      </material>
    </visual>
    <collision>
      <origin
        xyz="0 0 0"
        rpy="0 0 0" />
      <geometry>
        <mesh
          filename="package://armcontrol/meshes/v1.0/left_base_link.STL" />
      </geometry>
    </collision>
  </link>
  <link
    name="left_link1">
    <inertial>
      <origin
        xyz="-2.73173360270107E-05 -0.00628087149139267 0.0304831253798835"
        rpy="0 0 0" />
      <mass
        value="0.216375323075039" />
      <inertia
        ixx="0.000109047811784658"
        ixy="-4.14681401671785E-08"
        ixz="-2.40354087312248E-08"
        iyy="0.000107628449876935"
        iyz="1.65723685355677E-05"
        izz="9.33354303764178E-05" />
    </inertial>
    <visual>
      <origin
        xyz="0 0 0"
        rpy="0 0 0" />
      <geometry>
        <mesh
          filename="package://armcontrol/meshes/v1.0/left_link1.STL" />
      </geometry>
      <material
        name="">
        <color
          rgba="1 1 1 1" />
      </material>
    </visual>
    <collision>
      <origin
        xyz="0 0 0"
        rpy="0 0 0" />
      <geometry>
        <mesh
          filename="package://armcontrol/meshes/v1.0/left_link1.STL" />
      </geometry>
    </collision>
  </link>
  <joint
    name="left_joint1"
    type="revolute">
    <origin
      xyz="0 0 0.0695"
      rpy="0 0 0" />
    <parent
      link="left_base_link" />
    <child
      link="left_link1" />
    <axis
      xyz="0 0 1" />
    <limit
      lower="-3.14"
      upper="3.14"
      effort="0"
      velocity="0" />
  </joint>
  <link
    name="left_link2">
    <inertial>
      <origin
        xyz="0.094935 6.6235E-05 -0.015945"
        rpy="0 0 0" />
      <mass
        value="0.21621" />
      <inertia
        ixx="6.3537E-05"
        ixy="-8.7032E-08"
        ixz="-6.2646E-08"
        iyy="0.00021961"
        iyz="-2.31E-08"
        izz="0.00023963" />
    </inertial>
    <visual>
      <origin
        xyz="0 0 0"
        rpy="0 0 0" />
      <geometry>
        <mesh
          filename="package://armcontrol/meshes/v1.0/left_link2.STL" />
      </geometry>
      <material
        name="">
        <color
          rgba="1 1 1 1" />
      </material>
    </visual>
    <collision>
      <origin
        xyz="0 0 0"
        rpy="0 0 0" />
      <geometry>
        <mesh
          filename="package://armcontrol/meshes/v1.0/left_link2.STL" />
      </geometry>
    </collision>
  </link>
  <joint
    name="left_joint2"
    type="revolute">
    <origin
      xyz="0 0.03 0.0382"
      rpy="1.5708 0 -3.1416" />
    <parent
      link="left_link1" />
    <child
      link="left_link2" />
    <axis
      xyz="0 0 1" />
    <limit
      lower="-3.14"
      upper="3.14"
      effort="0"
      velocity="0" />
  </joint>
  <link
    name="left_link3">
    <inertial>
      <origin
        xyz="-0.0688726040682089 -9.86113155807544E-05 -0.0146805858392149"
        rpy="0 0 0" />
      <mass
        value="0.166370523958808" />
      <inertia
        ixx="7.9684297342547E-05"
        ixy="2.28017578079814E-07"
        ixz="-3.03924847648369E-05"
        iyy="0.000151090710051813"
        iyz="-2.37654703955376E-07"
        izz="0.000143465839269997" />
    </inertial>
    <visual>
      <origin
        xyz="0 0 0"
        rpy="0 0 0" />
      <geometry>
        <mesh
          filename="package://armcontrol/meshes/v1.0/left_link3.STL" />
      </geometry>
      <material
        name="">
        <color
          rgba="0.898039215686275 0.917647058823529 0.929411764705882 1" />
      </material>
    </visual>
    <collision>
      <origin
        xyz="0 0 0"
        rpy="0 0 0" />
      <geometry>
        <mesh
          filename="package://armcontrol/meshes/v1.0/left_link3.STL" />
      </geometry>
    </collision>
  </link>
  <joint
    name="left_joint3"
    type="revolute">
    <origin
      xyz="0.12 0.00010457 -0.0565"
      rpy="-3.1416 0 -3.1416" />
    <parent
      link="left_link2" />
    <child
      link="left_link3" />
    <axis
      xyz="0 0 1" />
    <limit
      lower="-3.14"
      upper="3.14"
      effort="0"
      velocity="0" />
  </joint>
  <link
    name="left_link4">
    <inertial>
      <origin
        xyz="8.6014E-05 -0.008367 0.016957"
        rpy="0 0 0" />
      <mass
        value="0.19095" />
      <inertia
        ixx="9.0708E-05"
        ixy="2.2827E-07"
        ixz="2.3762E-07"
        iyy="9.2778E-05"
        iyz="1.5095E-05"
        izz="7.9448E-05" />
    </inertial>
    <visual>
      <origin
        xyz="0 0 0"
        rpy="0 0 0" />
      <geometry>
        <mesh
          filename="package://armcontrol/meshes/v1.0/left_link4.STL" />
      </geometry>
      <material
        name="">
        <color
          rgba="0.89804 0.91765 0.92941 1" />
      </material>
    </visual>
    <collision>
      <origin
        xyz="0 0 0"
        rpy="0 0 0" />
      <geometry>
        <mesh
          filename="package://armcontrol/meshes/v1.0/left_link4.STL" />
      </geometry>
    </collision>
  </link>
  <joint
    name="left_joint4"
    type="revolute">
    <origin
      xyz="-0.128026044327395 0 -0.0265000000020573"
      rpy="-1.57079632679456 0 1.5707963267949" />
    <parent
      link="left_link3" />
    <child
      link="left_link4" />
    <axis
      xyz="0 0 1" />
    <limit
      lower="-3.14"
      upper="3.14"
      effort="0"
      velocity="0" />
  </joint>
  <link
    name="left_link5">
    <inertial>
      <origin
        xyz="3.0105257528612E-05 0.0384504305283764 -0.0159899794024814"
        rpy="0 0 0" />
      <mass
        value="0.171418755440487" />
      <inertia
        ixx="8.7840603330909E-05"
        ixy="7.17252854335588E-08"
        ixz="-1.0305075278253E-07"
        iyy="7.32897060309608E-05"
        iyz="1.57044936826167E-05"
        izz="8.35772253596485E-05" />
    </inertial>
    <visual>
      <origin
        xyz="0 0 0"
        rpy="0 0 0" />
      <geometry>
        <mesh
          filename="package://armcontrol/meshes/v1.0/left_link5.STL" />
      </geometry>
      <material
        name="">
        <color
          rgba="0.72156862745098 1 0.576470588235294 1" />
      </material>
    </visual>
    <collision>
      <origin
        xyz="0 0 0"
        rpy="0 0 0" />
      <geometry>
        <mesh
          filename="package://armcontrol/meshes/v1.0/left_link5.STL" />
      </geometry>
    </collision>
  </link>
  <joint
    name="left_joint5"
    type="revolute">
    <origin
      xyz="0 0.023 0.0362"
      rpy="1.5708 0 3.1416" />
    <parent
      link="left_link4" />
    <child
      link="left_link5" />
    <axis
      xyz="0 0 1" />
    <limit
      lower="-3.14"
      upper="3.14"
      effort="0"
      velocity="0" />
  </joint>
  <link
    name="left_link6">
    <inertial>
      <origin
        xyz="-5.4556E-13 -1.1782E-12 -0.015466"
        rpy="0 0 0" />
      <mass
        value="0.041017" />
      <inertia
        ixx="8.1591E-06"
        ixy="-3.462E-21"
        ixz="2.181E-19"
        iyy="8.1591E-06"
        iyz="-8.4703E-22"
        izz="9.7682E-06" />
    </inertial>
    <visual>
      <origin
        xyz="0 0 0"
        rpy="0 0 0" />
      <geometry>
        <mesh
          filename="package://armcontrol/meshes/v1.0/left_link6.STL" />
      </geometry>
      <material
        name="">
        <color
          rgba="0.72157 1 0.57647 1" />
      </material>
    </visual>
    <collision>
      <origin
        xyz="0 0 0"
        rpy="0 0 0" />
      <geometry>
        <mesh
          filename="package://armcontrol/meshes/v1.0/left_link6.STL" />
      </geometry>
    </collision>
  </link>
  <joint
    name="left_joint6"
    type="revolute">
    <origin
      xyz="0 0.098026 -0.023"
      rpy="1.5708 0 3.1416" />
    <parent
      link="left_link5" />
    <child
      link="left_link6" />
    <axis
      xyz="0 0 1" />
    <limit
      lower="-3.14"
      upper="3.14"
      effort="0"
      velocity="0" />
  </joint>
  <link name="left_gripper_base_link">
    <inertial>
      <origin
        xyz="-0.00005520 1.2341E-05 0.03296193"
        rpy="0 0 0" />
      <mass
        value="0.25641368" />
      <inertia
        ixx="4.6351E-04" ixy="-1.0E-08" ixz="-1.04E-06" iyy="4.4525E-04" iyz="-5.00E-08"
        izz="1.0438E-04" />
    </inertial>
    <visual>
      <origin rpy="0 0 0" xyz="0 0 0" />
      <geometry>
        <mesh filename="package://armcontrol/meshes/v1.0/gripper_base_link.STL" />
      </geometry>
      <material name="">
        <color rgba="0.89804 0.91765 0.92941 1" />
      </material>
    </visual>
  </link>
  <joint
    name="left_joint7"
    type="fixed">
    <origin
      xyz="0 0 0"
      rpy="0 0 -1.5708" />
    <parent
      link="left_link6" />
    <child
      link="left_gripper_base_link" />
    <axis
      xyz="0 0 1" />
    <limit
      lower="-3.14"
      upper="3.14"
      effort="0"
      velocity="0" />
  </joint>
  <link
    name="left_gripper_narrow1_Link">
    <inertial>
      <origin
        xyz="0.0094685 0.0068806 6.5437E-05"
        rpy="0 0 0" />
      <mass
        value="0.025428" />
      <inertia
        ixx="1.9574E-06"
        ixy="-4.2911E-07"
        ixz="-3.7111E-11"
        iyy="2.3919E-06"
        iyz="-3.008E-10"
        izz="1.5501E-06" />
    </inertial>
    <visual>
      <origin
        xyz="0 0 0"
        rpy="0 0 0" />
      <geometry>
        <mesh
          filename="package://armcontrol/meshes/v1.0/gripper_narrow1_Link.STL" />
      </geometry>
      <material
        name="">
        <color
          rgba="0.75294 0.75294 0.75294 1" />
      </material>
    </visual>
    <collision>
      <origin
        xyz="0 0 0"
        rpy="0 0 0" />
      <geometry>
        <mesh
          filename="package://armcontrol/meshes/v1.0/gripper_narrow1_Link.STL" />
      </geometry>
    </collision>
  </link>
  <joint
    name="left_gripper_narrow1_joint"
    type="fixed">
    <origin
      xyz="0 -0.0195 0.0565"
      rpy="-2.9951 -1.5708 -0.15964" />
    <parent
      link="left_gripper_base_link" />
    <child
      link="left_gripper_narrow1_Link" />
    <axis
      xyz="0 0 -1" />
    <limit
      lower="-3.14"
      upper="3.14"
      effort="0"
      velocity="0" />
  </joint>
  <link
    name="left_gripper_narrow2_Link">
    <inertial>
      <origin
        xyz="0.0088027 -0.007035 1.6424E-05"
        rpy="0 0 0" />
      <mass
        value="0.0040132" />
      <inertia
        ixx="1.0307E-07"
        ixy="5.7851E-08"
        ixz="9.5801E-11"
        iyy="1.1385E-07"
        iyz="-2.81E-11"
        izz="1.7009E-07" />
    </inertial>
    <visual>
      <origin
        xyz="0 0 0"
        rpy="0 0 0" />
      <geometry>
        <mesh
          filename="package://armcontrol/meshes/v1.0/gripper_narrow2_Link.STL" />
      </geometry>
      <material
        name="">
        <color
          rgba="0.75294 0.75294 0.75294 1" />
      </material>
    </visual>
    <collision>
      <origin
        xyz="0 0 0"
        rpy="0 0 0" />
      <geometry>
        <mesh
          filename="package://armcontrol/meshes/v1.0/gripper_narrow2_Link.STL" />
      </geometry>
    </collision>
  </link>
  <joint
    name="left_gripper_narrow2_joint"
    type="fixed">
    <origin
      xyz="0.030852 0.018551 0"
      rpy="0 0 0" />
    <parent
      link="left_gripper_narrow1_Link" />
    <child
      link="left_gripper_narrow2_Link" />
    <axis
      xyz="0 0 -1" />
    <limit
      lower="-3.14"
      upper="3.14"
      effort="0"
      velocity="0" />
  </joint>
  <link
    name="left_gripper_narrow3_Link">
    <inertial>
      <origin
        xyz="0.012508 -0.0079729 9.4339E-05"
        rpy="0 0 0" />
      <mass
        value="0.018029" />
      <inertia
        ixx="1.1403E-06"
        ixy="5.5159E-07"
        ixz="-4.0096E-13"
        iyy="2.5704E-06"
        iyz="1.0951E-12"
        izz="2.3252E-06" />
    </inertial>
    <visual>
      <origin
        xyz="0 0 0"
        rpy="0 0 0" />
      <geometry>
        <mesh
          filename="package://armcontrol/meshes/v1.0/gripper_narrow3_Link.STL" />
      </geometry>
      <material
        name="">
        <color
          rgba="0.75294 0.75294 0.75294 1" />
      </material>
    </visual>
    <collision>
      <origin
        xyz="0 0 0"
        rpy="0 0 0" />
      <geometry>
        <mesh
          filename="package://armcontrol/meshes/v1.0/gripper_narrow3_Link.STL" />
      </geometry>
    </collision>
  </link>
  <joint
    name="left_gripper_narrow3_joint"
    type="fixed">
    <origin
      xyz="0.018118 -0.01574 0"
      rpy="0 0 0" />
    <parent
      link="left_gripper_narrow2_Link" />
    <child
      link="left_gripper_narrow3_Link" />
    <axis
      xyz="0 0 -1" />
    <limit
      lower="-3.14"
      upper="3.14"
      effort="0"
      velocity="0" />
  </joint>
  <link
    name="left_gripper_narrow4_Link">
  </link>
  <joint
    name="left_gripper_narrow4_joint"
    type="fixed">
    <origin
      xyz="0 -0.0104 0"
      rpy="0 0 0" />
    <parent
      link="left_gripper_narrow3_Link" />
    <child
      link="left_gripper_narrow4_Link" />
    <axis
      xyz="0 0 1" />
    <limit
      lower="-3.14"
      upper="3.14"
      effort="0"
      velocity="0" />
  </joint>
  <link
    name="left_gripper_narrow_loop_Link">
    <inertial>
      <origin
        xyz="0.014869 -0.0036066 0.00029307"
        rpy="0 0 0" />
      <mass
        value="0.022591" />
      <inertia
        ixx="4.3916E-06"
        ixy="1.114E-07"
        ixz="-4.9655E-12"
        iyy="4.737E-06"
        iyz="1.7121E-11"
        izz="6.0445E-07" />
    </inertial>
    <visual>
      <origin
        xyz="0 0 0"
        rpy="0 0 0" />
      <geometry>
        <mesh
          filename="package://armcontrol/meshes/v1.0/gripper_narrow_loop_Link.STL" />
      </geometry>
      <material
        name="">
        <color
          rgba="0.75294 0.75294 0.75294 1" />
      </material>
    </visual>
    <collision>
      <origin
        xyz="0 0 0"
        rpy="0 0 0" />
      <geometry>
        <mesh
          filename="package://armcontrol/meshes/v1.0/gripper_narrow_loop_Link.STL" />
      </geometry>
    </collision>
  </link>
  <joint
    name="left_gripper_narrow_loop_joint"
    type="fixed">
    <origin
      xyz="0 -0.021633 0.07387"
      rpy="-2.9951 -1.5708 -0.15964" />
    <parent
      link="left_gripper_base_link" />
    <child
      link="left_gripper_narrow_loop_Link" />
    <axis
      xyz="0 0 -1" />
    <limit
      lower="-3.14"
      upper="3.14"
      effort="0"
      velocity="0" />
  </joint>
  <link
    name="left_gripper_wide1_Link">
    <inertial>
      <origin
        xyz="0.0095051 -0.0068479 6.8268E-05"
        rpy="0 0 0" />
      <mass
        value="0.025428" />
      <inertia
        ixx="1.9565E-06"
        ixy="4.2798E-07"
        ixz="2.3844E-10"
        iyy="2.3928E-06"
        iyz="-1.4454E-10"
        izz="1.5501E-06" />
    </inertial>
    <visual>
      <origin
        xyz="0 0 0"
        rpy="0 0 0" />
      <geometry>
        <mesh
          filename="package://armcontrol/meshes/v1.0/gripper_wide1_Link.STL" />
      </geometry>
      <material
        name="">
        <color
          rgba="0.75294 0.75294 0.75294 1" />
      </material>
    </visual>
    <collision>
      <origin
        xyz="0 0 0"
        rpy="0 0 0" />
      <geometry>
        <mesh
          filename="package://armcontrol/meshes/v1.0/gripper_wide1_Link.STL" />
      </geometry>
    </collision>
  </link>
  <joint
    name="left_gripper_wide1_joint"
    type="fixed">
    <origin
      xyz="0 0.0195 0.0565"
      rpy="-2.9951 -1.5708 -0.15964" />
    <parent
      link="left_gripper_base_link" />
    <child
      link="left_gripper_wide1_Link" />
    <axis
      xyz="0 0 -1" />
    <limit
      lower="-3.14"
      upper="3.14"
      effort="0"
      velocity="0" />
  </joint>
  <link
    name="left_gripper_wide2_Link">
    <inertial>
      <origin
        xyz="0.0088027 0.007035 -1.6424E-05"
        rpy="0 0 0" />
      <mass
        value="0.0040132" />
      <inertia
        ixx="1.0307E-07"
        ixy="-5.7851E-08"
        ixz="-9.58E-11"
        iyy="1.1385E-07"
        iyz="-2.81E-11"
        izz="1.7009E-07" />
    </inertial>
    <visual>
      <origin
        xyz="0 0 0"
        rpy="0 0 0" />
      <geometry>
        <mesh
          filename="package://armcontrol/meshes/v1.0/gripper_wide2_Link.STL" />
      </geometry>
      <material
        name="">
        <color
          rgba="0.75294 0.75294 0.75294 1" />
      </material>
    </visual>
    <collision>
      <origin
        xyz="0 0 0"
        rpy="0 0 0" />
      <geometry>
        <mesh
          filename="package://armcontrol/meshes/v1.0/gripper_wide2_Link.STL" />
      </geometry>
    </collision>
  </link>
  <joint
    name="left_gripper_wide2_joint"
    type="fixed">
    <origin
      xyz="0.030852 -0.018551 0"
      rpy="0 0 0" />
    <parent
      link="left_gripper_wide1_Link" />
    <child
      link="left_gripper_wide2_Link" />
    <axis
      xyz="0 0 -1" />
    <limit
      lower="-3.14"
      upper="3.14"
      effort="0"
      velocity="0" />
  </joint>
  <link
    name="left_gripper_wide3_Link">
    <inertial>
      <origin
        xyz="0.016206 0.0094593 4.7668E-05"
        rpy="0 0 0" />
      <mass
        value="0.035835" />
      <inertia
        ixx="8.5056E-06"
        ixy="-1.1363E-06"
        ixz="-4.2908E-11"
        iyy="1.1235E-05"
        iyz="-2.9251E-11"
        izz="4.6309E-06" />
    </inertial>
    <visual>
      <origin
        xyz="0 0 0"
        rpy="0 0 0" />
      <geometry>
        <mesh
          filename="package://armcontrol/meshes/v1.0/gripper_wide3_Link.STL" />
      </geometry>
      <material
        name="">
        <color
          rgba="0.75294 0.75294 0.75294 1" />
      </material>
    </visual>
    <collision>
      <origin
        xyz="0 0 0"
        rpy="0 0 0" />
      <geometry>
        <mesh
          filename="package://armcontrol/meshes/v1.0/gripper_wide3_Link.STL" />
      </geometry>
    </collision>
  </link>
  <joint
    name="left_gripper_wide3_joint"
    type="fixed">
    <origin
      xyz="0.018118 0.01574 0"
      rpy="0 0 0" />
    <parent
      link="left_gripper_wide2_Link" />
    <child
      link="left_gripper_wide3_Link" />
    <axis
      xyz="0 0 -1" />
    <limit
      lower="-3.14"
      upper="3.14"
      effort="0"
      velocity="0" />
  </joint>
  <link
    name="left_gripper_wide4_Link">
  </link>
  <joint
    name="left_gripper_wide4_joint"
    type="fixed">
    <origin
      xyz="0 0.0104 0"
      rpy="0 0 0" />
    <parent
      link="left_gripper_wide3_Link" />
    <child
      link="left_gripper_wide4_Link" />
    <axis
      xyz="0 0 1" />
    <limit
      lower="-3.14"
      upper="3.14"
      effort="0"
      velocity="0" />
  </joint>
  <link
    name="left_gripper_wide_loop_Link">
    <inertial>
      <origin
        xyz="0.016268 0.0040555 0.00030323"
        rpy="0 0 0" />
      <mass
        value="0.025142" />
      <inertia
        ixx="5.887E-06"
        ixy="-1.1234E-07"
        ixz="2.1954E-11"
        iyy="6.236E-06"
        iyz="-9.473E-12"
        izz="6.2389E-07" />
    </inertial>
    <visual>
      <origin
        xyz="0 0 0"
        rpy="0 0 0" />
      <geometry>
        <mesh
          filename="package://armcontrol/meshes/v1.0/gripper_wide_loop_Link.STL" />
      </geometry>
      <material
        name="">
        <color
          rgba="0.75294 0.75294 0.75294 1" />
      </material>
    </visual>
    <collision>
      <origin
        xyz="0 0 0"
        rpy="0 0 0" />
      <geometry>
        <mesh
          filename="package://armcontrol/meshes/v1.0/gripper_wide_loop_Link.STL" />
      </geometry>
    </collision>
  </link>
  <joint
    name="left_gripper_wide_loop_joint"
    type="fixed">
    <origin
      xyz="0 0.021633 0.07387"
      rpy="-2.9951 -1.5708 -0.15964" />
    <parent
      link="left_gripper_base_link" />
    <child
      link="left_gripper_wide_loop_Link" />
    <axis
      xyz="0 0 -1" />
    <limit
      lower="-3.14"
      upper="3.14"
      effort="0"
      velocity="0" />
  </joint>
  <link
    name="left_load" />
  <joint name="left_load_joint" type="fixed">
    <origin
      xyz="0 0 0.17"
      rpy="0 0 0" />
    <parent
      link="left_gripper_base_link" />
    <child
      link="left_load" />
  </joint>

  <link
    name="right_base_link">
    <inertial>
      <origin
        xyz="-2.9876E-05 -1.5665E-05 -0.024802"
        rpy="0 0 0" />
      <mass
        value="0.24339" />
      <inertia
        ixx="9.5419E-05"
        ixy="8.1102E-09"
        ixz="4.892E-08"
        iyy="9.5361E-05"
        iyz="2.7733E-08"
        izz="0.00014543" />
    </inertial>
    <visual>
      <origin
        xyz="0 0 0"
        rpy="0 0 0" />
      <geometry>
        <mesh
          filename="package://armcontrol/meshes/v1.0/right_base_link.STL" />
      </geometry>
      <material
        name="">
        <color
          rgba="1 1 1 1" />
      </material>
    </visual>
    <collision>
      <origin
        xyz="0 0 0"
        rpy="0 0 0" />
      <geometry>
        <mesh
          filename="package://armcontrol/meshes/v1.0/right_base_link.STL" />
      </geometry>
    </collision>
  </link>
  <link
    name="right_link1">
    <inertial>
      <origin
        xyz="-2.7310542500103E-05 -0.00628087219832218 -0.0304300316492992"
        rpy="0 0 0" />
      <mass
        value="0.216375332848476" />
      <inertia
        ixx="0.000109047818711104"
        ixy="-4.14567028961551E-08"
        ixz="-2.39585802054231E-08"
        iyy="0.000107628457195037"
        iyz="-1.64969319150789E-05"
        izz="9.333542918741E-05" />
    </inertial>
    <visual>
      <origin
        xyz="0 0 0"
        rpy="0 0 0" />
      <geometry>
        <mesh
          filename="package://armcontrol/meshes/v1.0/right_link1.STL" />
      </geometry>
      <material
        name="">
        <color
          rgba="1 1 1 1" />
      </material>
    </visual>
    <collision>
      <origin
        xyz="0 0 0"
        rpy="0 0 0" />
      <geometry>
        <mesh
          filename="package://armcontrol/meshes/v1.0/right_link1.STL" />
      </geometry>
    </collision>
  </link>
  <joint
    name="right_joint1"
    type="revolute">
    <origin
      xyz="0 0 -0.0695"
      rpy="0 0 0" />
    <parent
      link="right_base_link" />
    <child
      link="right_link1" />
    <axis
      xyz="0 0 -1" />
    <limit
      lower="-3.14"
      upper="3.14"
      effort="0"
      velocity="0" />
  </joint>
  <link
    name="right_link2">
    <inertial>
      <origin
        xyz="0.0949346250684329 6.62350913162024E-05 -0.0159445965178503"
        rpy="0 0 0" />
      <mass
        value="0.216210437047529" />
      <inertia
        ixx="6.35367956230124E-05"
        ixy="-8.7031605433986E-08"
        ixz="-6.26461196304298E-08"
        iyy="0.000219608893174189"
        iyz="-2.310024539718E-08"
        izz="0.000239633346857777" />
    </inertial>
    <visual>
      <origin
        xyz="0 0 0"
        rpy="0 0 0" />
      <geometry>
        <mesh
          filename="package://armcontrol/meshes/v1.0/right_link2.STL" />
      </geometry>
      <material
        name="">
        <color
          rgba="1 1 1 1" />
      </material>
    </visual>
    <collision>
      <origin
        xyz="0 0 0"
        rpy="0 0 0" />
      <geometry>
        <mesh
          filename="package://armcontrol/meshes/v1.0/right_link2.STL" />
      </geometry>
    </collision>
  </link>
  <joint
    name="right_joint2"
    type="revolute">
    <origin
      xyz="0 0.03 -0.0382"
      rpy="1.5708 0 -3.1416" />
    <parent
      link="right_link1" />
    <child
      link="right_link2" />
    <axis
      xyz="0 0 1" />
    <limit
      lower="-3.14"
      upper="3.14"
      effort="0"
      velocity="0" />
  </joint>
  <link
    name="right_link3">
    <inertial>
      <origin
        xyz="-0.0688726040682089 -9.86113155806989E-05 -0.0146805858392149"
        rpy="0 0 0" />
      <mass
        value="0.166370523958808" />
      <inertia
        ixx="7.9684297342547E-05"
        ixy="2.28017578079814E-07"
        ixz="-3.03924847648369E-05"
        iyy="0.000151090710051813"
        iyz="-2.37654703955376E-07"
        izz="0.000143465839269997" />
    </inertial>
    <visual>
      <origin
        xyz="0 0 0"
        rpy="0 0 0" />
      <geometry>
        <mesh
          filename="package://armcontrol/meshes/v1.0/right_link3.STL" />
      </geometry>
      <material
        name="">
        <color
          rgba="0.898039215686275 0.917647058823529 0.929411764705882 1" />
      </material>
    </visual>
    <collision>
      <origin
        xyz="0 0 0"
        rpy="0 0 0" />
      <geometry>
        <mesh
          filename="package://armcontrol/meshes/v1.0/right_link3.STL" />
      </geometry>
    </collision>
  </link>
  <joint
    name="right_joint3"
    type="revolute">
    <origin
      xyz="0.12 0.00010457 -0.0565"
      rpy="-3.1416 0 -3.1416" />
    <parent
      link="right_link2" />
    <child
      link="right_link3" />
    <axis
      xyz="0 0 1" />
    <limit
      lower="-3.14"
      upper="3.14"
      effort="0"
      velocity="0" />
  </joint>
  <link
    name="right_link4">
    <inertial>
      <origin
        xyz="8.60138389621734E-05 -0.00836699240857486 0.0169570253314204"
        rpy="0 0 0" />
      <mass
        value="0.190948393076664" />
      <inertia
        ixx="9.07081686907845E-05"
        ixy="2.28272715385657E-07"
        ixz="2.37623395129417E-07"
        iyy="9.27776269302402E-05"
        iyz="1.50952302629617E-05"
        izz="7.94476687104766E-05" />
    </inertial>
    <visual>
      <origin
        xyz="0 0 0"
        rpy="0 0 0" />
      <geometry>
        <mesh
          filename="package://armcontrol/meshes/v1.0/right_link4.STL" />
      </geometry>
      <material
        name="">
        <color
          rgba="0.898039215686275 0.917647058823529 0.929411764705882 1" />
      </material>
    </visual>
    <collision>
      <origin
        xyz="0 0 0"
        rpy="0 0 0" />
      <geometry>
        <mesh
          filename="package://armcontrol/meshes/v1.0/right_link4.STL" />
      </geometry>
    </collision>
  </link>
  <joint
    name="right_joint4"
    type="revolute">
    <origin
      xyz="-0.12803 0 -0.0265"
      rpy="-1.5708 0 1.5708" />
    <parent
      link="right_link3" />
    <child
      link="right_link4" />
    <axis
      xyz="0 0 1" />
    <limit
      lower="-3.14"
      upper="3.14"
      effort="0"
      velocity="0" />
  </joint>
  <link
    name="right_link5">
    <inertial>
      <origin
        xyz="3.0105257528612E-05 0.0384504305283764 -0.0159899794024815"
        rpy="0 0 0" />
      <mass
        value="0.171418755440487" />
      <inertia
        ixx="8.78406033309087E-05"
        ixy="7.1725285433576E-08"
        ixz="-1.03050752782563E-07"
        iyy="7.32897060309607E-05"
        iyz="1.57044936826167E-05"
        izz="8.35772253596482E-05" />
    </inertial>
    <visual>
      <origin
        xyz="0 0 0"
        rpy="0 0 0" />
      <geometry>
        <mesh
          filename="package://armcontrol/meshes/v1.0/right_link5.STL" />
      </geometry>
      <material
        name="">
        <color
          rgba="0.72156862745098 1 0.576470588235294 1" />
      </material>
    </visual>
    <collision>
      <origin
        xyz="0 0 0"
        rpy="0 0 0" />
      <geometry>
        <mesh
          filename="package://armcontrol/meshes/v1.0/right_link5.STL" />
      </geometry>
    </collision>
  </link>
  <joint
    name="right_joint5"
    type="revolute">
    <origin
      xyz="0 0.023 0.0362"
      rpy="1.5708 0 3.1416" />
    <parent
      link="right_link4" />
    <child
      link="right_link5" />
    <axis
      xyz="0 0 1" />
    <limit
      lower="-3.14"
      upper="3.14"
      effort="0"
      velocity="0" />
  </joint>
  <link
    name="right_link6">
    <inertial>
      <origin
        xyz="-5.45563594300802E-13 -1.17822418488345E-12 -0.0154663947605964"
        rpy="0 0 0" />
      <mass
        value="0.0410166336852684" />
      <inertia
        ixx="8.15913513447814E-06"
        ixy="-3.46387404400587E-21"
        ixz="2.18101352925825E-19"
        iyy="8.15913513447814E-06"
        iyz="-8.470329472543E-22"
        izz="9.76816264773412E-06" />
    </inertial>
    <visual>
      <origin
        xyz="0 0 0"
        rpy="0 0 0" />
      <geometry>
        <mesh
          filename="package://armcontrol/meshes/v1.0/right_link6.STL" />
      </geometry>
      <material
        name="">
        <color
          rgba="0.72156862745098 1 0.576470588235294 1" />
      </material>
    </visual>
    <collision>
      <origin
        xyz="0 0 0"
        rpy="0 0 0" />
      <geometry>
        <mesh
          filename="package://armcontrol/meshes/v1.0/right_link6.STL" />
      </geometry>
    </collision>
  </link>
  <joint
    name="right_joint6"
    type="revolute">
    <origin
      xyz="0 0.098026 -0.023"
      rpy="1.5708 0 3.1416" />
    <parent
      link="right_link5" />
    <child
      link="right_link6" />
    <axis
      xyz="0 0 1" />
    <limit
      lower="-3.14"
      upper="3.14"
      effort="0"
      velocity="0" />
  </joint>
  <link name="right_gripper_base_link">
    <inertial>
      <origin
        xyz="-0.00005520 1.2341E-05 0.03296193"
        rpy="0 0 0" />
      <mass
        value="0.25641368" />
      <inertia
        ixx="4.6351E-04" ixy="-1.0E-08" ixz="-1.04E-06" iyy="4.4525E-04" iyz="-5.00E-08"
        izz="1.0438E-04" />
    </inertial>
    <visual>
      <origin rpy="0 0 0" xyz="0 0 0" />
      <geometry>
        <mesh filename="package://armcontrol/meshes/v1.0/gripper_base_link.STL" />
      </geometry>
      <material name="">
        <color rgba="0.89804 0.91765 0.92941 1" />
      </material>
    </visual>
  </link>
  <joint
    name="right_joint7"
    type="fixed">
    <origin
      xyz="0 0 0"
      rpy="0 0 1.5708" />
    <parent
      link="right_link6" />
    <child
      link="right_gripper_base_link" />
    <axis
      xyz="0 0 1" />
    <limit
      lower="-3.14"
      upper="3.14"
      effort="0"
      velocity="0" />
  </joint>
  <link
    name="right_gripper_narrow1_Link">
    <inertial>
      <origin
        xyz="0.0094685 0.0068806 6.5437E-05"
        rpy="0 0 0" />
      <mass
        value="0.025428" />
      <inertia
        ixx="1.9574E-06"
        ixy="-4.2911E-07"
        ixz="-3.7111E-11"
        iyy="2.3919E-06"
        iyz="-3.008E-10"
        izz="1.5501E-06" />
    </inertial>
    <visual>
      <origin
        xyz="0 0 0"
        rpy="0 0 0" />
      <geometry>
        <mesh
          filename="package://armcontrol/meshes/v1.0/gripper_narrow1_Link.STL" />
      </geometry>
      <material
        name="">
        <color
          rgba="0.75294 0.75294 0.75294 1" />
      </material>
    </visual>
    <collision>
      <origin
        xyz="0 0 0"
        rpy="0 0 0" />
      <geometry>
        <mesh
          filename="package://armcontrol/meshes/v1.0/gripper_narrow1_Link.STL" />
      </geometry>
    </collision>
  </link>
  <joint
    name="right_gripper_narrow1_joint"
    type="fixed">
    <origin
      xyz="0 -0.0195 0.0565"
      rpy="-2.9951 -1.5708 -0.15964" />
    <parent
      link="right_gripper_base_link" />
    <child
      link="right_gripper_narrow1_Link" />
    <axis
      xyz="0 0 -1" />
    <limit
      lower="-3.14"
      upper="3.14"
      effort="0"
      velocity="0" />
  </joint>
  <link
    name="right_gripper_narrow2_Link">
    <inertial>
      <origin
        xyz="0.0088027 -0.007035 1.6424E-05"
        rpy="0 0 0" />
      <mass
        value="0.0040132" />
      <inertia
        ixx="1.0307E-07"
        ixy="5.7851E-08"
        ixz="9.5801E-11"
        iyy="1.1385E-07"
        iyz="-2.81E-11"
        izz="1.7009E-07" />
    </inertial>
    <visual>
      <origin
        xyz="0 0 0"
        rpy="0 0 0" />
      <geometry>
        <mesh
          filename="package://armcontrol/meshes/v1.0/gripper_narrow2_Link.STL" />
      </geometry>
      <material
        name="">
        <color
          rgba="0.75294 0.75294 0.75294 1" />
      </material>
    </visual>
    <collision>
      <origin
        xyz="0 0 0"
        rpy="0 0 0" />
      <geometry>
        <mesh
          filename="package://armcontrol/meshes/v1.0/gripper_narrow2_Link.STL" />
      </geometry>
    </collision>
  </link>
  <joint
    name="right_gripper_narrow2_joint"
    type="fixed">
    <origin
      xyz="0.030852 0.018551 0"
      rpy="0 0 0" />
    <parent
      link="right_gripper_narrow1_Link" />
    <child
      link="right_gripper_narrow2_Link" />
    <axis
      xyz="0 0 -1" />
    <limit
      lower="-3.14"
      upper="3.14"
      effort="0"
      velocity="0" />
  </joint>
  <link
    name="right_gripper_narrow3_Link">
    <inertial>
      <origin
        xyz="0.012508 -0.0079729 9.4339E-05"
        rpy="0 0 0" />
      <mass
        value="0.018029" />
      <inertia
        ixx="1.1403E-06"
        ixy="5.5159E-07"
        ixz="-4.0096E-13"
        iyy="2.5704E-06"
        iyz="1.0951E-12"
        izz="2.3252E-06" />
    </inertial>
    <visual>
      <origin
        xyz="0 0 0"
        rpy="0 0 0" />
      <geometry>
        <mesh
          filename="package://armcontrol/meshes/v1.0/gripper_narrow3_Link.STL" />
      </geometry>
      <material
        name="">
        <color
          rgba="0.75294 0.75294 0.75294 1" />
      </material>
    </visual>
    <collision>
      <origin
        xyz="0 0 0"
        rpy="0 0 0" />
      <geometry>
        <mesh
          filename="package://armcontrol/meshes/v1.0/gripper_narrow3_Link.STL" />
      </geometry>
    </collision>
  </link>
  <joint
    name="right_gripper_narrow3_joint"
    type="fixed">
    <origin
      xyz="0.018118 -0.01574 0"
      rpy="0 0 0" />
    <parent
      link="right_gripper_narrow2_Link" />
    <child
      link="right_gripper_narrow3_Link" />
    <axis
      xyz="0 0 -1" />
    <limit
      lower="-3.14"
      upper="3.14"
      effort="0"
      velocity="0" />
  </joint>
  <link
    name="right_gripper_narrow4_Link">
  </link>
  <joint
    name="right_gripper_narrow4_joint"
    type="fixed">
    <origin
      xyz="0 -0.0104 0"
      rpy="0 0 0" />
    <parent
      link="right_gripper_narrow3_Link" />
    <child
      link="right_gripper_narrow4_Link" />
    <axis
      xyz="0 0 1" />
    <limit
      lower="-3.14"
      upper="3.14"
      effort="0"
      velocity="0" />
  </joint>
  <link
    name="right_gripper_narrow_loop_Link">
    <inertial>
      <origin
        xyz="0.014869 -0.0036066 0.00029307"
        rpy="0 0 0" />
      <mass
        value="0.022591" />
      <inertia
        ixx="4.3916E-06"
        ixy="1.114E-07"
        ixz="-4.9655E-12"
        iyy="4.737E-06"
        iyz="1.7121E-11"
        izz="6.0445E-07" />
    </inertial>
    <visual>
      <origin
        xyz="0 0 0"
        rpy="0 0 0" />
      <geometry>
        <mesh
          filename="package://armcontrol/meshes/v1.0/gripper_narrow_loop_Link.STL" />
      </geometry>
      <material
        name="">
        <color
          rgba="0.75294 0.75294 0.75294 1" />
      </material>
    </visual>
    <collision>
      <origin
        xyz="0 0 0"
        rpy="0 0 0" />
      <geometry>
        <mesh
          filename="package://armcontrol/meshes/v1.0/gripper_narrow_loop_Link.STL" />
      </geometry>
    </collision>
  </link>
  <joint
    name="right_gripper_narrow_loop_joint"
    type="fixed">
    <origin
      xyz="0 -0.021633 0.07387"
      rpy="-2.9951 -1.5708 -0.15964" />
    <parent
      link="right_gripper_base_link" />
    <child
      link="right_gripper_narrow_loop_Link" />
    <axis
      xyz="0 0 -1" />
    <limit
      lower="-3.14"
      upper="3.14"
      effort="0"
      velocity="0" />
  </joint>
  <link
    name="right_gripper_wide1_Link">
    <inertial>
      <origin
        xyz="0.0095051 -0.0068479 6.8268E-05"
        rpy="0 0 0" />
      <mass
        value="0.025428" />
      <inertia
        ixx="1.9565E-06"
        ixy="4.2798E-07"
        ixz="2.3844E-10"
        iyy="2.3928E-06"
        iyz="-1.4454E-10"
        izz="1.5501E-06" />
    </inertial>
    <visual>
      <origin
        xyz="0 0 0"
        rpy="0 0 0" />
      <geometry>
        <mesh
          filename="package://armcontrol/meshes/v1.0/gripper_wide1_Link.STL" />
      </geometry>
      <material
        name="">
        <color
          rgba="0.75294 0.75294 0.75294 1" />
      </material>
    </visual>
    <collision>
      <origin
        xyz="0 0 0"
        rpy="0 0 0" />
      <geometry>
        <mesh
          filename="package://armcontrol/meshes/v1.0/gripper_wide1_Link.STL" />
      </geometry>
    </collision>
  </link>
  <joint
    name="right_gripper_wide1_joint"
    type="fixed">
    <origin
      xyz="0 0.0195 0.0565"
      rpy="-2.9951 -1.5708 -0.15964" />
    <parent
      link="right_gripper_base_link" />
    <child
      link="right_gripper_wide1_Link" />
    <axis
      xyz="0 0 -1" />
    <limit
      lower="-3.14"
      upper="3.14"
      effort="0"
      velocity="0" />
  </joint>
  <link
    name="right_gripper_wide2_Link">
    <inertial>
      <origin
        xyz="0.0088027 0.007035 -1.6424E-05"
        rpy="0 0 0" />
      <mass
        value="0.0040132" />
      <inertia
        ixx="1.0307E-07"
        ixy="-5.7851E-08"
        ixz="-9.58E-11"
        iyy="1.1385E-07"
        iyz="-2.81E-11"
        izz="1.7009E-07" />
    </inertial>
    <visual>
      <origin
        xyz="0 0 0"
        rpy="0 0 0" />
      <geometry>
        <mesh
          filename="package://armcontrol/meshes/v1.0/gripper_wide2_Link.STL" />
      </geometry>
      <material
        name="">
        <color
          rgba="0.75294 0.75294 0.75294 1" />
      </material>
    </visual>
    <collision>
      <origin
        xyz="0 0 0"
        rpy="0 0 0" />
      <geometry>
        <mesh
          filename="package://armcontrol/meshes/v1.0/gripper_wide2_Link.STL" />
      </geometry>
    </collision>
  </link>
  <joint
    name="right_gripper_wide2_joint"
    type="fixed">
    <origin
      xyz="0.030852 -0.018551 0"
      rpy="0 0 0" />
    <parent
      link="right_gripper_wide1_Link" />
    <child
      link="right_gripper_wide2_Link" />
    <axis
      xyz="0 0 -1" />
    <limit
      lower="-3.14"
      upper="3.14"
      effort="0"
      velocity="0" />
  </joint>
  <link
    name="right_gripper_wide3_Link">
    <inertial>
      <origin
        xyz="0.016206 0.0094593 4.7668E-05"
        rpy="0 0 0" />
      <mass
        value="0.035835" />
      <inertia
        ixx="8.5056E-06"
        ixy="-1.1363E-06"
        ixz="-4.2908E-11"
        iyy="1.1235E-05"
        iyz="-2.9251E-11"
        izz="4.6309E-06" />
    </inertial>
    <visual>
      <origin
        xyz="0 0 0"
        rpy="0 0 0" />
      <geometry>
        <mesh
          filename="package://armcontrol/meshes/v1.0/gripper_wide3_Link.STL" />
      </geometry>
      <material
        name="">
        <color
          rgba="0.75294 0.75294 0.75294 1" />
      </material>
    </visual>
    <collision>
      <origin
        xyz="0 0 0"
        rpy="0 0 0" />
      <geometry>
        <mesh
          filename="package://armcontrol/meshes/v1.0/gripper_wide3_Link.STL" />
      </geometry>
    </collision>
  </link>
  <joint
    name="right_gripper_wide3_joint"
    type="fixed">
    <origin
      xyz="0.018118 0.01574 0"
      rpy="0 0 0" />
    <parent
      link="right_gripper_wide2_Link" />
    <child
      link="right_gripper_wide3_Link" />
    <axis
      xyz="0 0 -1" />
    <limit
      lower="-3.14"
      upper="3.14"
      effort="0"
      velocity="0" />
  </joint>
  <link
    name="right_gripper_wide4_Link">
  </link>
  <joint
    name="right_gripper_wide4_joint"
    type="fixed">
    <origin
      xyz="0 0.0104 0"
      rpy="0 0 0" />
    <parent
      link="right_gripper_wide3_Link" />
    <child
      link="right_gripper_wide4_Link" />
    <axis
      xyz="0 0 1" />
    <limit
      lower="-3.14"
      upper="3.14"
      effort="0"
      velocity="0" />
  </joint>
  <link
    name="right_gripper_wide_loop_Link">
    <inertial>
      <origin
        xyz="0.016268 0.0040555 0.00030323"
        rpy="0 0 0" />
      <mass
        value="0.025142" />
      <inertia
        ixx="5.887E-06"
        ixy="-1.1234E-07"
        ixz="2.1954E-11"
        iyy="6.236E-06"
        iyz="-9.473E-12"
        izz="6.2389E-07" />
    </inertial>
    <visual>
      <origin
        xyz="0 0 0"
        rpy="0 0 0" />
      <geometry>
        <mesh
          filename="package://armcontrol/meshes/v1.0/gripper_wide_loop_Link.STL" />
      </geometry>
      <material
        name="">
        <color
          rgba="0.75294 0.75294 0.75294 1" />
      </material>
    </visual>
    <collision>
      <origin
        xyz="0 0 0"
        rpy="0 0 0" />
      <geometry>
        <mesh
          filename="package://armcontrol/meshes/v1.0/gripper_wide_loop_Link.STL" />
      </geometry>
    </collision>
  </link>
  <joint
    name="right_gripper_wide_loop_joint"
    type="fixed">
    <origin
      xyz="0 0.021633 0.07387"
      rpy="-2.9951 -1.5708 -0.15964" />
    <parent
      link="right_gripper_base_link" />
    <child
      link="right_gripper_wide_loop_Link" />
    <axis
      xyz="0 0 -1" />
    <limit
      lower="-3.14"
      upper="3.14"
      effort="0"
      velocity="0" />
  </joint>
  <link
    name="right_load" />
  <joint name="right_load_joint" type="fixed">
    <origin
      xyz="0 0 0.17"
      rpy="0 0 0" />
    <parent
      link="right_gripper_base_link" />
    <child
      link="right_load" />
  </joint>

  <joint
    name="left_base_joint"
    type="fixed">
    <origin
      xyz="-0.1 0 1.2"
      rpy="1.5708 -1.5708 -1.5708" />
    <parent
      link="base" />
    <child
      link="left_base_link" />
  </joint>
  <joint
    name="right_base_joint"
    type="fixed">
    <origin
      xyz="0.1 0 1.2"
      rpy="-1.5708 -1.5708 1.5708" />
    <parent
      link="base" />
    <child
      link="right_base_link" />
  </joint>

</robot>